Workbook

Sheet Mode d'emploi
A1: Boutique de Maman : liste de départ
A3: Ce fichier sert à créer le compte de Maman avec tous ses articles, prix et stock déjà en place.
A4: Remplir uniquement les cases jaunes de l'onglet « Articles ».
A6: Colonne | B6: Quoi écrire
A7: Prix d'achat (F) | B7: Ce que Maman paie pour UNE pièce chez son fournisseur. Sert à calculer le bénéfice. Laisser vide si on ne sait pas, on pourra le mettre plus tard.
A8: Prix détail (F) | B8: Prix d'une pièce vendue au détail. Nombre entier, sans « F » ni espace. Les cases rouges n'ont pas encore de prix.
A9: Prix gros (F) | B9: Prix d'UNE pièce quand elle vend en gros. Laisser vide si elle ne vend pas cet article en gros.
A10: Stock de départ | B10: Nombre de pièces comptées en boutique le jour du démarrage. Vide = 0.
A11: Nouvel article | B11: Utiliser les lignes vides en bas de l'onglet : choisir la catégorie, écrire le nom, puis les prix.
A12: Supprimer | B12: Effacer toute la ligne (nom compris). Une ligne sans nom est ignorée.
A14: Exemple | B14: Mèches | Bella | 1800 | 2500 | 2150 | 6
A16: Articles dans la liste | B16: =COUNTA(Articles!B2:B357) -> 316
A17: Prix détail encore manquants | B17: =COUNTIFS(Articles!B2:B357,"<>",Articles!D2:D357,"") -> 43
A18: Prix d'achat encore manquants | B18: =COUNTIFS(Articles!B2:B357,"<>",Articles!C2:C357,"") -> 316
A19: Pièces en stock au total | B19: =SUM(Articles!F2:F357) -> 0
A20: Valeur du stock au prix détail (F) | B20: =SUMPRODUCT(Articles!D2:D357,Articles!F2:F357) -> 0
A21: Valeur du stock au prix d'achat (F) | B21: =SUMPRODUCT(Articles!C2:C357,Articles!F2:F357) -> 0
A23: Attention aux noms à vérifier | B23: Certains noms contiennent un prix ou un lot (ex. « Dallas grand 3/4400 »). Corrigez le nom si besoin et mettez le vrai prix dans les colonnes.

Sheet Articles
A1: Catégorie | B1: Désignation | C1: Prix d'achat (F) | D1: Prix détail (F) | E1: Prix gros (F) | F1: Stock de départ | G1: Remarque
A2: Mèches | B2: 4 flowers | D2: 1400 | G2: =IF(B2="","",IF(D2="","Prix détail manquant",IF(AND(E2<>"",E2>D2),"Prix gros plus cher que détail ?",IF(AND(C2<>"",C2>=D2),"Vendu à perte ?",IF(AND(C2<>"",E2<>"",C2>=E2),"Gros vendu à perte ?","")))))
A3: Mèches | B3: 4pcs | D3: 3000 | G3: =IF(B3="","",IF(D3="","Prix détail manquant",IF(AND(E3<>"",E3>D3),"Prix gros plus cher que détail ?",IF(AND(C3<>"",C3>=D3),"Vendu à perte ?",IF(AND(C3<>"",E3<>"",C3>=E3),"Gros vendu à perte ?","")))))
A4: Mèches | B4: 8 amies amaka | D4: 1500 | G4: =IF(B4="","",IF(D4="","Prix détail manquant",IF(AND(E4<>"",E4>D4),"Prix gros plus cher que détail ?",IF(AND(C4<>"",C4>=D4),"Vendu à perte ?",IF(AND(C4<>"",E4<>"",C4>=E4),"Gros vendu à perte ?","")))))
A5: Mèches | B5: Active | D5: 2200 | G5: =IF(B5="","",IF(D5="","Prix détail manquant",IF(AND(E5<>"",E5>D5),"Prix gros plus cher que détail ?",IF(AND(C5<>"",C5>=D5),"Vendu à perte ?",IF(AND(C5<>"",E5<>"",C5>=E5),"Gros vendu à perte ?","")))))
A6: Mèches | B6: Adorable | D6: 5000 | G6: =IF(B6="","",IF(D6="","Prix détail manquant",IF(AND(E6<>"",E6>D6),"Prix gros plus cher que détail ?",IF(AND(C6<>"",C6>=D6),"Vendu à perte ?",IF(AND(C6<>"",E6<>"",C6>=E6),"Gros vendu à perte ?","")))))
A7: Mèches | B7: Afro pondo grd | D7: 1335 | G7: =IF(B7="","",IF(D7="","Prix détail manquant",IF(AND(E7<>"",E7>D7),"Prix gros plus cher que détail ?",IF(AND(C7<>"",C7>=D7),"Vendu à perte ?",IF(AND(C7<>"",E7<>"",C7>=E7),"Gros vendu à perte ?","")))))
A8: Mèches | B8: Amanda | D8: 1670 | G8: =IF(B8="","",IF(D8="","Prix détail manquant",IF(AND(E8<>"",E8>D8),"Prix gros plus cher que détail ?",IF(AND(C8<>"",C8>=D8),"Vendu à perte ?",IF(AND(C8<>"",E8<>"",C8>=E8),"Gros vendu à perte ?","")))))
A9: Mèches | B9: ANI Spring | D9: 3500 | G9: =IF(B9="","",IF(D9="","Prix détail manquant",IF(AND(E9<>"",E9>D9),"Prix gros plus cher que détail ?",IF(AND(C9<>"",C9>=D9),"Vendu à perte ?",IF(AND(C9<>"",E9<>"",C9>=E9),"Gros vendu à perte ?","")))))
A10: Mèches | B10: Ari-C | D10: 3000 | G10: =IF(B10="","",IF(D10="","Prix détail manquant",IF(AND(E10<>"",E10>D10),"Prix gros plus cher que détail ?",IF(AND(C10<>"",C10>=D10),"Vendu à perte ?",IF(AND(C10<>"",E10<>"",C10>=E10),"Gros vendu à perte ?","")))))
A11: Mèches | B11: Bamba plus grand | D11: 4500 | G11: =IF(B11="","",IF(D11="","Prix détail manquant",IF(AND(E11<>"",E11>D11),"Prix gros plus cher que détail ?",IF(AND(C11<>"",C11>=D11),"Vendu à perte ?",IF(AND(C11<>"",E11<>"",C11>=E11),"Gros vendu à perte ?","")))))
A12: Mèches | B12: Bella | D12: 2500 | G12: =IF(B12="","",IF(D12="","Prix détail manquant",IF(AND(E12<>"",E12>D12),"Prix gros plus cher que détail ?",IF(AND(C12<>"",C12>=D12),"Vendu à perte ?",IF(AND(C12<>"",E12<>"",C12>=E12),"Gros vendu à perte ?","")))))
A13: Mèches | B13: Boho water culy | D13: 2000 | G13: =IF(B13="","",IF(D13="","Prix détail manquant",IF(AND(E13<>"",E13>D13),"Prix gros plus cher que détail ?",IF(AND(C13<>"",C13>=D13),"Vendu à perte ?",IF(AND(C13<>"",E13<>"",C13>=E13),"Gros vendu à perte ?","")))))
... A29: Mèches | B29: Cozy vert pt | D29: 1170 | G29: =IF(B29="","",IF(D29="","Prix détail manquant",IF(AND(E29<>"",E29>D29),"Prix gros plus cher que détail ?",IF(AND(C29<>"",C29>=D29),"Vendu à perte ?",IF(AND(C29<>"",E29<>"",C29>=E29),"Gros vendu à perte ?","")))))
A30: Mèches | B30: Cro chili locs | G30: =IF(B30="","",IF(D30="","Prix détail manquant",IF(AND(E30<>"",E30>D30),"Prix gros plus cher que détail ?",IF(AND(C30<>"",C30>=D30),"Vendu à perte ?",IF(AND(C30<>"",E30<>"",C30>=E30),"Gros vendu à perte ?",""))))) -> Prix détail manquant
A31: Mèches | B31: Cro elim | D31: 3500 | G31: =IF(B31="","",IF(D31="","Prix détail manquant",IF(AND(E31<>"",E31>D31),"Prix gros plus cher que détail ?",IF(AND(C31<>"",C31>=D31),"Vendu à perte ?",IF(AND(C31<>"",E31<>"",C31>=E31),"Gros vendu à perte ?","")))))
A32: Mèches | B32: Cro Full pock | D32: 3500 | G32: =IF(B32="","",IF(D32="","Prix détail manquant",IF(AND(E32<>"",E32>D32),"Prix gros plus cher que détail ?",IF(AND(C32<>"",C32>=D32),"Vendu à perte ?",IF(AND(C32<>"",E32<>"",C32>=E32),"Gros vendu à perte ?","")))))
A33: Mèches | B33: Cro gini | D33: 5000 | G33: =IF(B33="","",IF(D33="","Prix détail manquant",IF(AND(E33<>"",E33>D33),"Prix gros plus cher que détail ?",IF(AND(C33<>"",C33>=D33),"Vendu à perte ?",IF(AND(C33<>"",E33<>"",C33>=E33),"Gros vendu à perte ?","")))))
A34: Mèches | B34: Cro lulu | D34: 3500 | G34: =IF(B34="","",IF(D34="","Prix détail manquant",IF(AND(E34<>"",E34>D34),"Prix gros plus cher que détail ?",IF(AND(C34<>"",C34>=D34),"Vendu à perte ?",IF(AND(C34<>"",E34<>"",C34>=E34),"Gros vendu à perte ?","")))))
A35: Mèches | B35: Cro sultant | D35: 4000 | G35: =IF(B35="","",IF(D35="","Prix détail manquant",IF(AND(E35<>"",E35>D35),"Prix gros plus cher que détail ?",IF(AND(C35<>"",C35>=D35),"Vendu à perte ?",IF(AND(C35<>"",E35<>"",C35>=E35),"Gros vendu à perte ?","")))))
A36: Mèches | B36: Cro unique | D36: 3800 | G36: =IF(B36="","",IF(D36="","Prix détail manquant",IF(AND(E36<>"",E36>D36),"Prix gros plus cher que détail ?",IF(AND(C36<>"",C36>=D36),"Vendu à perte ?",IF(AND(C36<>"",E36<>"",C36>=E36),"Gros vendu à perte ?","")))))
A37: Mèches | B37: Cro vill dread | D37: 3000 | G37: =IF(B37="","",IF(D37="","Prix détail manquant",IF(AND(E37<>"",E37>D37),"Prix gros plus cher que détail ?",IF(AND(C37<>"",C37>=D37),"Vendu à perte ?",IF(AND(C37<>"",E37<>"",C37>=E37),"Gros vendu à perte ?","")))))
A38: Mèches | B38: Cro-baby | D38: 5000 | G38: =IF(B38="","",IF(D38="","Prix détail manquant",IF(AND(E38<>"",E38>D38),"Prix gros plus cher que détail ?",IF(AND(C38<>"",C38>=D38),"Vendu à perte ?",IF(AND(C38<>"",E38<>"",C38>=E38),"Gros vendu à perte ?","")))))
A39: Mèches | B39: Cro-meg | D39: 5000 | G39: =IF(B39="","",IF(D39="","Prix détail manquant",IF(AND(E39<>"",E39>D39),"Prix gros plus cher que détail ?",IF(AND(C39<>"",C39>=D39),"Vendu à perte ?",IF(AND(C39<>"",E39<>"",C39>=E39),"Gros vendu à perte ?","")))))
A40: Mèches | B40: Crochet Aviv churk | D40: 2500 | G40: =IF(B40="","",IF(D40="","Prix détail manquant",IF(AND(E40<>"",E40>D40),"Prix gros plus cher que détail ?",IF(AND(C40<>"",C40>=D40),"Vendu à perte ?",IF(AND(C40<>"",E40<>"",C40>=E40),"Gros vendu à perte ?","")))))
A41: Mèches | B41: Crochet culy twit braid | D41: 1800 | G41: =IF(B41="","",IF(D41="","Prix détail manquant",IF(AND(E41<>"",E41>D41),"Prix gros plus cher que détail ?",IF(AND(C41<>"",C41>=D41),"Vendu à perte ?",IF(AND(C41<>"",E41<>"",C41>=E41),"Gros vendu à perte ?","")))))
A42: Mèches | B42: Crochet Liz twist | D42: 4500 | G42: =IF(B42="","",IF(D42="","Prix détail manquant",IF(AND(E42<>"",E42>D42),"Prix gros plus cher que détail ?",IF(AND(C42<>"",C42>=D42),"Vendu à perte ?",IF(AND(C42<>"",E42<>"",C42>=E42),"Gros vendu à perte ?","")))))
A43: Mèches | B43: Crochet max locs | D43: 5000 | G43: =IF(B43="","",IF(D43="","Prix détail manquant",IF(AND(E43<>"",E43>D43),"Prix gros plus cher que détail ?",IF(AND(C43<>"",C43>=D43),"Vendu à perte ?",IF(AND(C43<>"",E43<>"",C43>=E43),"Gros vendu à perte ?","")))))
A44: Mèches | B44: Crochet pristine | G44: =IF(B44="","",IF(D44="","Prix détail manquant",IF(AND(E44<>"",E44>D44),"Prix gros plus cher que détail ?",IF(AND(C44<>"",C44>=D44),"Vendu à perte ?",IF(AND(C44<>"",E44<>"",C44>=E44),"Gros vendu à perte ?",""))))) -> Prix détail manquant
A45: Mèches | B45: Crochet shasha | D45: 3800 | G45: =IF(B45="","",IF(D45="","Prix détail manquant",IF(AND(E45<>"",E45>D45),"Prix gros plus cher que détail ?",IF(AND(C45<>"",C45>=D45),"Vendu à perte ?",IF(AND(C45<>"",E45<>"",C45>=E45),"Gros vendu à perte ?","")))))
A46: Mèches | B46: Croflout locs plus | D46: 4800 | G46: =IF(B46="","",IF(D46="","Prix détail manquant",IF(AND(E46<>"",E46>D46),"Prix gros plus cher que détail ?",IF(AND(C46<>"",C46>=D46),"Vendu à perte ?",IF(AND(C46<>"",E46<>"",C46>=E46),"Gros vendu à perte ?","")))))
A47: Mèches | B47: Cully boby | D47: 4000 | G47: =IF(B47="","",IF(D47="","Prix détail manquant",IF(AND(E47<>"",E47>D47),"Prix gros plus cher que détail ?",IF(AND(C47<>"",C47>=D47),"Vendu à perte ?",IF(AND(C47<>"",E47<>"",C47>=E47),"Gros vendu à perte ?","")))))
A48: Mèches | B48: Curly braid | D48: 3500 | G48: =IF(B48="","",IF(D48="","Prix détail manquant",IF(AND(E48<>"",E48>D48),"Prix gros plus cher que détail ?",IF(AND(C48<>"",C48>=D48),"Vendu à perte ?",IF(AND(C48<>"",E48<>"",C48>=E48),"Gros vendu à perte ?","")))))
A49: Mèches | B49: Dada locs | D49: 3500 | G49: =IF(B49="","",IF(D49="","Prix détail manquant",IF(AND(E49<>"",E49>D49),"Prix gros plus cher que détail ?",IF(AND(C49<>"",C49>=D49),"Vendu à perte ?",IF(AND(C49<>"",E49<>"",C49>=E49),"Gros vendu à perte ?","")))))
A50: Mèches | B50: Daniela sublime | D50: 1670 | G50: =IF(B50="","",IF(D50="","Prix détail manquant",IF(AND(E50<>"",E50>D50),"Prix gros plus cher que détail ?",IF(AND(C50<>"",C50>=D50),"Vendu à perte ?",IF(AND(C50<>"",E50<>"",C50>=E50),"Gros vendu à perte ?","")))))
A51: Mèches | B51: Daniella | D51: 1500 | G51: =IF(B51="","",IF(D51="","Prix détail manquant",IF(AND(E51<>"",E51>D51),"Prix gros plus cher que détail ?",IF(AND(C51<>"",C51>=D51),"Vendu à perte ?",IF(AND(C51<>"",E51<>"",C51>=E51),"Gros vendu à perte ?","")))))
A52: Mèches | B52: Daniellax2 | D52: 2000 | G52: =IF(B52="","",IF(D52="","Prix détail manquant",IF(AND(E52<>"",E52>D52),"Prix gros plus cher que détail ?",IF(AND(C52<>"",C52>=D52),"Vendu à perte ?",IF(AND(C52<>"",E52<>"",C52>=E52),"Gros vendu à perte ?","")))))
A53: Mèches | B53: Deep weave | D53: 2500 | G53: =IF(B53="","",IF(D53="","Prix détail manquant",IF(AND(E53<>"",E53>D53),"Prix gros plus cher que détail ?",IF(AND(C53<>"",C53>=D53),"Vendu à perte ?",IF(AND(C53<>"",E53<>"",C53>=E53),"Gros vendu à perte ?","")))))
A54: Mèches | B54: Dejava | D54: 1800 | G54: =IF(B54="","",IF(D54="","Prix détail manquant",IF(AND(E54<>"",E54>D54),"Prix gros plus cher que détail ?",IF(AND(C54<>"",C54>=D54),"Vendu à perte ?",IF(AND(C54<>"",E54<>"",C54>=E54),"Gros vendu à perte ?","")))))
A55: Mèches | B55: Deluxe | D55: 4000 | G55: =IF(B55="","",IF(D55="","Prix détail manquant",IF(AND(E55<>"",E55>D55),"Prix gros plus cher que détail ?",IF(AND(C55<>"",C55>=D55),"Vendu à perte ?",IF(AND(C55<>"",E55<>"",C55>=E55),"Gros vendu à perte ?","")))))
...
