Workbook

Sheet Mode d'emploi
A1: Import du stock MÈCHES — fiche papier (5 pages)
A3: Prix : même prix en gros et en détail (confirmé par Maman).
A4: Couleurs : ORANGE = raturé, surchargé ou nom à confirmer → vérifier avec Maman et corriger. JAUNE = prix manquant. BLEU = renommé ou ajouté.
A5: Règles : chiffre seul = unités ; 1 dz = 12 ; « - » = 0 ; case vide = 0 (à confirmer).
A6: La colonne « Prix sur la fiche » contient le prix écrit sur la fiche (avec les corrections de Maman au stylo bleu).
A7: Pour corriger un stock ou une entrée : modifier les colonnes J (Stock en unités) et K (Entrées en unités). Le STOCK FINAL se recalcule.
A9: Résumé :
A10: Articles au total | B10: =COUNTA('Import mèches'!D2:D161) -> 160
A11: Articles ajoutés | B11: =COUNTIF('Import mèches'!B2:B161,"Ajouter") -> 45
A12: Articles renommés | B12: =COUNTIF('Import mèches'!B2:B161,"Renommer") -> 11
A13: Stock total (unités) | B13: =SUM('Import mèches'!L2:L161) -> 1072
A14: Prix manquants | B14: =COUNTBLANK('Import mèches'!G2:G161) -> 10

Sheet Import mèches
A1: N° | B1: Action | C1: Nom actuel (app) | D1: Nom final | E1: Catégorie | F1: Prix actuel app (F) | G1: Prix gros = détail (F) | H1: Stock écrit | I1: Entrées écrites | J1: Stock (unités) | K1: Entrées (unités) | L1: STOCK FINAL | M1: À vérifier
A2: 1 | B2: Garder | C2: 4 flowers | D2: 4 flowers | E2: Mèches | F2: 1400 | G2: 1500 | H2: 04 | J2: 4 | K2: 0 | L2: =J2+K2 -> 4 | M2: Prix changé : 1400 → 1500
A3: 2 | B3: Renommer | C3: 4pcs | D3: AFRO-B | E3: Mèches | F3: 3000 | G3: 3000 | H3: 00 | I3: 12 | J3: 0 | K3: 12 | L3: =J3+K3 -> 12 | M3: « 4pcs » barré, remplacé par « AFRO-B »
A4: 3 | B4: Garder | C4: 8 amies amaka | D4: 8 amies amaka | E4: Mèches | F4: 1500 | G4: 1500 | H4: 00 | J4: 0 | K4: 0 | L4: =J4+K4 -> 0
A5: 4 | B5: Garder | C5: Active | D5: Active | E5: Mèches | F5: 2200 | G5: 2200 | H5: (vide) | J5: 0 | K5: 0 | L5: =J5+K5 -> 0 | M5: Case stock vide sur la fiche (compté 0)
A6: 5 | B6: Garder | C6: Adorable | D6: Adorable | E6: Mèches | F6: 5000 | G6: 5000 | H6: (vide) | J6: 0 | K6: 0 | L6: =J6+K6 -> 0 | M6: Case stock vide sur la fiche (compté 0)
A7: 6 | B7: Garder | C7: Afro pondo grd | D7: Afro pondo grd | E7: Mèches | F7: 1335 | G7: 1700 | H7: 15 | J7: 15 | K7: 0 | L7: =J7+K7 -> 15 | M7: Prix changé : 1335 → 1700
A8: 7 | B8: Garder | C8: Amanda | D8: Amanda | E8: Mèches | F8: 1670 | G8: 2000 | H8: 04 | J8: 4 | K8: 0 | L8: =J8+K8 -> 4 | M8: Prix changé : 1670 → 2000
A9: 8 | B9: Garder | C9: ANI Spring | D9: ANI Spring | E9: Mèches | F9: 3500 | G9: 3500 | H9: 05 | J9: 5 | K9: 0 | L9: =J9+K9 -> 5
A10: 9 | B10: Garder | C10: Ari-C | D10: Ari-C | E10: Mèches | F10: 3000 | G10: 3000 | H10: 02 | J10: 2 | K10: 0 | L10: =J10+K10 -> 2
A11: 10 | B11: Garder | C11: Bamba plus grand | D11: Bamba plus grand | E11: Mèches | F11: 4500 | G11: 4500 | H11: - | J11: 0 | K11: 0 | L11: =J11+K11 -> 0
A12: 11 | B12: Garder | C12: Bella | D12: Bella | E12: Mèches | F12: 2500 | G12: 2500 | H12: - | J12: 0 | K12: 0 | L12: =J12+K12 -> 0
A13: 12 | B13: Garder | C13: Boho water culy | D13: Boho water culy | E13: Mèches | F13: 2000 | G13: 2200 | H13: 05 | J13: 5 | K13: 0 | L13: =J13+K13 -> 5 | M13: Prix changé : 2000 → 2200
A14: 13 | B14: Garder | C14: Bomba plus | D14: Bomba plus | E14: Mèches | F14: 2800 | G14: 2800 | H14: 02 | J14: 2 | K14: 0 | L14: =J14+K14 -> 2
A15: 14 | B15: Garder | C15: Bon-street | D15: Bon-street | E15: Mèches | F15: 2000 | G15: 2000 | H15: 02 | J15: 2 | K15: 0 | L15: =J15+K15 -> 2
A16: 15 | B16: Garder | C16: Bounce | D16: Bounce | E16: Mèches | F16: 1600 | G16: 1600 | H16: - | J16: 0 | K16: 0 | L16: =J16+K16 -> 0
A17: 16 | B17: Garder | C17: Bouncy kinky | D17: Bouncy kinky | E17: Mèches | F17: 2000 | G17: 2200 | H17: 36 | J17: 36 | K17: 0 | L17: =J17+K17 -> 36 | M17: Prix changé : 2000 → 2200
A18: 17 | B18: Garder | C18: Brillant | D18: Brillant | E18: Mèches | F18: 2000 | G18: 2000 | H18: - | J18: 0 | K18: 0 | L18: =J18+K18 -> 0
A19: 18 | B19: Garder | C19: Burtherfly twist grd | D19: Burtherfly twist grd | E19: Mèches | F19: 4000 | G19: 4000 | H19: 02 | J19: 2 | K19: 0 | L19: =J19+K19 -> 2
A20: 19 | B20: Garder | C20: Butterfly twist pt | D20: Butterfly twist pt | E20: Mèches | F20: 3500 | G20: 3500 | H20: 02 | J20: 2 | K20: 0 | L20: =J20+K20 -> 2
A21: 20 | B21: Garder | C21: Celina locs | D21: Celina locs | E21: Mèches | F21: 4000 | G21: 4000 | H21: - | J21: 0 | K21: 0 | L21: =J21+K21 -> 0
A22: 21 | B22: Garder | C22: Ceres | D22: Ceres | E22: Mèches | F22: 1400 | G22: 1500 | H22: 52 | J22: 52 | K22: 0 | L22: =J22+K22 -> 52 | M22: Prix changé : 1400 → 1500
A23: 22 | B23: Garder | C23: Chery | D23: Chery | E23: Mèches | F23: 5500 | G23: 6000 | H23: - | J23: 0 | K23: 0 | L23: =J23+K23 -> 0 | M23: Prix changé : 5500 → 6000
A24: 23 | B24: Garder | C24: Clara tissage | D24: Clara tissage | E24: Mèches | F24: 9000 | G24: 9000 | H24: 01 | J24: 1 | K24: 0 | L24: =J24+K24 -> 1
A25: 24 | B25: Garder | C25: Closure | D25: Closure | E25: Mèches | F25: 2500 | G25: 2500 | H25: 01 | J25: 1 | K25: 0 | L25: =J25+K25 -> 1
A26: 25 | B26: Garder | C26: Corde noir | D26: Corde noir | E26: Mèches | F26: 500 | G26: 500 | H26: 22dz5 | J26: 269 | K26: 0 | L26: =J26+K26 -> 269
A27: 26 | B27: Renommer | C27: Corde noir1500 Baby | D27: Corde noir Baby (douzaine) | E27: Mèches | F27: 170 | G27: 2500 | H27: 5 | J27: 5 | K27: 0 | L27: =J27+K27 -> 5 | M27: Vendu à la douzaine (2500 F) : stock 5 douzaines ; les 4 pièces restantes sont sur la ligne « Corde noir Baby (pièce) » Prix changé : 170 → 2500
A28: 27 | B28: Garder | C28: Cozi original | D28: Cozi original | E28: Mèches | F28: 1170 | G28: 1170 | H28: (vide) | J28: 0 | K28: 0 | L28: =J28+K28 -> 0 | M28: Case stock vide sur la fiche (compté 0)
A29: 28 | B29: Garder | C29: Cozy vert pt | D29: Cozy vert pt | E29: Mèches | F29: 1170 | G29: 1170 | H29: 16 | J29: 16 | K29: 0 | L29: =J29+K29 -> 16
A30: 29 | B30: Garder | C30: Cro chili locs | D30: Cro chili locs | E30: Mèches | G30: 3000 | H30: 01 | J30: 1 | K30: 0 | L30: =J30+K30 -> 1
A31: 30 | B31: Garder | C31: Cro elim | D31: Cro elim | E31: Mèches | F31: 3500 | G31: 3500 | H31: 06 | J31: 6 | K31: 0 | L31: =J31+K31 -> 6
A32: 31 | B32: Renommer | C32: Cro Full pock | D32: Cro Braiden | E32: Mèches | F32: 3500 | G32: 3500 | I32: 02 | J32: 0 | K32: 2 | L32: =J32+K32 -> 2 | M32: « Full pock » barré → « Braiden »
A33: 32 | B33: Renommer | C33: Cro gini | D33: Cro Zara | E33: Mèches | F33: 5000 | G33: 5000 | I33: 03 | J33: 0 | K33: 3 | L33: =J33+K33 -> 3 | M33: « gint » barré → « Zara »
A34: 33 | B34: Renommer | C34: Cro lulu | D34: Cro Summer locs | E34: Mèches | F34: 3500 | G34: 3500 | I34: 04 | J34: 0 | K34: 4 | L34: =J34+K34 -> 4 | M34: « lulu » barré → « Summer locs »
A35: 34 | B35: Garder | C35: Cro sultant | D35: Cro sultant | E35: Mèches | F35: 4000 | G35: 4000 | H35: 00 | J35: 0 | K35: 0 | L35: =J35+K35 -> 0
A36: 35 | B36: Garder | C36: Cro unique | D36: Cro unique | E36: Mèches | F36: 3800 | G36: 3800 | H36: 02 | J36: 2 | K36: 0 | L36: =J36+K36 -> 2
A37: 36 | B37: Garder | C37: Cro vill dread | D37: Cro vill dread | E37: Mèches | F37: 3000 | G37: 3000 | H37: 02 | J37: 2 | K37: 0 | L37: =J37+K37 -> 2
A38: 37 | B38: Renommer | C38: Cro-baby | D38: Banny | E38: Mèches | F38: 5000 | G38: 5000 | H38: 01 | J38: 1 | K38: 0 | L38: =J38+K38 -> 1
A39: 38 | B39: Garder | C39: Crochet Aviv churk | D39: Crochet Aviv churk | E39: Mèches | F39: 2500 | G39: 2500 | H39: 01 | J39: 1 | K39: 0 | L39: =J39+K39 -> 1
A40: 39 | B40: Renommer | C40: Crochet culy twit braid | D40: Crochet Miya braid | E40: Mèches | F40: 1800 | G40: 1800 | H40: 00 | I40: 02 | J40: 0 | K40: 2 | L40: =J40+K40 -> 2
...
