Workbook

Sheet Mode d'emploi
A1: Import du stock PRODUITS — à compléter avec Maman
A3: Couleurs :
A4: JAUNE = à remplir : prix gros manquants (col. F) et PRIX DÉTAIL (col. Q, tous les articles).
A5: IMPORTANT : la colonne F contient le prix GROS d'une unité (et non le prix détail). Le prix détail est à demander à Maman (col. Q).
A6: ORANGE = chiffre raturé ou peu lisible sur la fiche : vérifier sur la vraie feuille et corriger les colonnes J à N.
A7: BLEU = article renommé ou ajouté.
A9: Règles appliquées : chiffre seul = unités ; 1 dz = 12 unités ; P = paquet, ct = carton (nombre d'unités à indiquer) ; « -3 » = 3 unités retirées ; « - » ou « = » = 0.
A10: La colonne O « STOCK FINAL » se calcule toute seule. Elle affiche « à compléter » tant qu'il manque le nombre d'unités d'un paquet ou d'un carton.
A12: Si Maman a vendu des articles depuis le jour du comptage, enlève-les du stock final (ou enregistre ces ventes dans l'app après l'import).
A14: Renommés : Barrette blanc grand → Barrette multicolor ; Like à sec Petit → Like argan ; Peigne complet → Perle de 4000 (4000 F) ; Piques → Pince grand ; Tam-tam overa → Tam-tam xblock ; Peigne afro petit → Peigne afro petit de 100 (100 F).
A15: Ajoutés : Perle de 3500, Peigne afro petit de 150, et les 24 articles écrits à la main (dont Fer à brosse et Coris attaché).
A16: Retirés (Action = Retirer) : « Colle Ultra », « Passion twist » et le Tam-tam xblock vide créé au 1er import. Les quantités peuvent avoir des décimales (ex. 12,5 : Maman vend certaines perles à la demi-unité).
A18: Résumé (se met à jour tout seul) :
A19: Lignes au total | B19: =COUNTA('Import produits'!D2:D229) -> 228
A20: Stock final calculé | B20: =COUNT('Import produits'!O2:O229) -> 228
A21: Stock final « à compléter » | B21: =COUNTIF('Import produits'!O2:O229,"à compléter") -> 0
A22: Lignes à vérifier (lecture incertaine) | B22: =COUNTIF('Import produits'!P2:P229,"*incertaine*") -> 0
A23: Prix gros manquants | B23: =COUNTBLANK('Import produits'!F2:F229) -> 5
A24: Prix détail à remplir | B24: =COUNTBLANK('Import produits'!Q2:Q229) -> 205

Sheet Import produits
A1: N° | B1: Action | C1: Nom actuel (app) | D1: Nom final | E1: Catégorie | F1: Prix GROS (F, 1 unité) | G1: Stock écrit | H1: Entrées écrites | I1: Retirés | J1: Unités (hors paquets/cartons) | K1: Nb paquets | L1: Unités dans 1 paquet | M1: Nb cartons | N1: Unités dans 1 carton | O1: STOCK FINAL (unités) | P1: À vérifier | Q1: Prix DÉTAIL (F, 1 unité) — à demander à Maman
A2: 1 | B2: Garder | C2: Aiguille | D2: Aiguille | E2: Produits | F2: 170 | G2: 87 | J2: 87 | O2: =IF(AND(J2="",K2="",M2=""),"",IF(OR(AND(N(K2)>0,L2=""),AND(N(M2)>0,N2="")),"à compléter",N(J2)+N(K2)*N(L2)+N(M2)*N(N2))) -> 87
A3: 2 | B3: Garder | C3: Apperl | D3: Apperl | E3: Produits | F3: 335 | G3: 16 | J3: 16 | O3: =IF(AND(J3="",K3="",M3=""),"",IF(OR(AND(N(K3)>0,L3=""),AND(N(M3)>0,N3="")),"à compléter",N(J3)+N(K3)*N(L3)+N(M3)*N(N3))) -> 16
A4: 3 | B4: Garder | C4: Avocado de 1800 | D4: Avocado de 1800 | E4: Produits | F4: 1800 | G4: - | J4: 0 | O4: =IF(AND(J4="",K4="",M4=""),"",IF(OR(AND(N(K4)>0,L4=""),AND(N(M4)>0,N4="")),"à compléter",N(J4)+N(K4)*N(L4)+N(M4)*N(N4))) -> 0
A5: 4 | B5: Garder | C5: Avocado grand 3 | D5: Avocado grand 3 | E5: Produits | F5: 1100 | G5: 27 | J5: 27 | O5: =IF(AND(J5="",K5="",M5=""),"",IF(OR(AND(N(K5)>0,L5=""),AND(N(M5)>0,N5="")),"à compléter",N(J5)+N(K5)*N(L5)+N(M5)*N(N5))) -> 27
A6: 5 | B6: Garder | C6: Ballon de 1300 | D6: Ballon de 1300 | E6: Produits | F6: 1300 | G6: 05 | J6: 5 | O6: =IF(AND(J6="",K6="",M6=""),"",IF(OR(AND(N(K6)>0,L6=""),AND(N(M6)>0,N6="")),"à compléter",N(J6)+N(K6)*N(L6)+N(M6)*N(N6))) -> 5
A7: 6 | B7: Garder | C7: Bande à fleur | D7: Bande à fleur | E7: Produits | F7: 500 | G7: 28 | J7: 28 | O7: =IF(AND(J7="",K7="",M7=""),"",IF(OR(AND(N(K7)>0,L7=""),AND(N(M7)>0,N7="")),"à compléter",N(J7)+N(K7)*N(L7)+N(M7)*N(N7))) -> 28
A8: 7 | B8: Garder | C8: Bande cheveux petit | D8: Bande cheveux petit | E8: Produits | F8: 300 | G8: 2 | J8: 2 | O8: =IF(AND(J8="",K8="",M8=""),"",IF(OR(AND(N(K8)>0,L8=""),AND(N(M8)>0,N8="")),"à compléter",N(J8)+N(K8)*N(L8)+N(M8)*N(N8))) -> 2
A9: 8 | B9: Garder | C9: Bande chouchou | D9: Bande chouchou | E9: Produits | F9: 500 | G9: 2 | J9: 2 | O9: =IF(AND(J9="",K9="",M9=""),"",IF(OR(AND(N(K9)>0,L9=""),AND(N(M9)>0,N9="")),"à compléter",N(J9)+N(K9)*N(L9)+N(M9)*N(N9))) -> 2
A10: 9 | B10: Garder | C10: Bande grand | D10: Bande grand | E10: Produits | F10: 500 | G10: 4 | J10: 4 | O10: =IF(AND(J10="",K10="",M10=""),"",IF(OR(AND(N(K10)>0,L10=""),AND(N(M10)>0,N10="")),"à compléter",N(J10)+N(K10)*N(L10)+N(M10)*N(N10))) -> 4
A11: 10 | B11: Garder | C11: Bande noir | D11: Bande noir | E11: Produits | F11: 300 | G11: 26 | J11: 26 | O11: =IF(AND(J11="",K11="",M11=""),"",IF(OR(AND(N(K11)>0,L11=""),AND(N(M11)>0,N11="")),"à compléter",N(J11)+N(K11)*N(L11)+N(M11)*N(N11))) -> 26
A12: 11 | B12: Garder | C12: Barrette blanc | D12: Barrette blanc | E12: Produits | F12: 335 | G12: 5dz6 | J12: 66 | O12: =IF(AND(J12="",K12="",M12=""),"",IF(OR(AND(N(K12)>0,L12=""),AND(N(M12)>0,N12="")),"à compléter",N(J12)+N(K12)*N(L12)+N(M12)*N(N12))) -> 66
A13: 12 | B13: Renommer | C13: Barrette blanc grand | D13: Barrette multicolor | E13: Produits | F13: 400 | G13: 1dz10 | J13: 22 | O13: =IF(AND(J13="",K13="",M13=""),"",IF(OR(AND(N(K13)>0,L13=""),AND(N(M13)>0,N13="")),"à compléter",N(J13)+N(K13)*N(L13)+N(M13)*N(N13))) -> 22
... A17: 16 | B17: Garder | C17: Barrette papillon | D17: Barrette papillon | E17: Produits | F17: 1500 | G17: 5dz | J17: 60 | O17: =IF(AND(J17="",K17="",M17=""),"",IF(OR(AND(N(K17)>0,L17=""),AND(N(M17)>0,N17="")),"à compléter",N(J17)+N(K17)*N(L17)+N(M17)*N(N17))) -> 60
A18: 17 | B18: Garder | C18: Barrette petit | D18: Barrette petit | E18: Produits | F18: 300 | G18: 07dz | H18: 40dz | J18: 564 | O18: =IF(AND(J18="",K18="",M18=""),"",IF(OR(AND(N(K18)>0,L18=""),AND(N(M18)>0,N18="")),"à compléter",N(J18)+N(K18)*N(L18)+N(M18)*N(N18))) -> 564
A19: 18 | B19: Garder | C19: Barrette piquet | D19: Barrette piquet | E19: Produits | F19: 85 | G19: 94 | J19: 94 | O19: =IF(AND(J19="",K19="",M19=""),"",IF(OR(AND(N(K19)>0,L19=""),AND(N(M19)>0,N19="")),"à compléter",N(J19)+N(K19)*N(L19)+N(M19)*N(N19))) -> 94
A20: 19 | B20: Garder | C20: Barrette piquet grand | D20: Barrette piquet grand | E20: Produits | F20: 150 | G20: 08 | J20: 8 | O20: =IF(AND(J20="",K20="",M20=""),"",IF(OR(AND(N(K20)>0,L20=""),AND(N(M20)>0,N20="")),"à compléter",N(J20)+N(K20)*N(L20)+N(M20)*N(N20))) -> 8
A21: 20 | B21: Garder | C21: Black Magic | D21: Black Magic | E21: Produits | F21: 500 | J21: 0 | O21: =IF(AND(J21="",K21="",M21=""),"",IF(OR(AND(N(K21)>0,L21=""),AND(N(M21)>0,N21="")),"à compléter",N(J21)+N(K21)*N(L21)+N(M21)*N(N21))) -> 0 | P21: Stock vide sur la fiche
A22: 21 | B22: Garder | C22: Bobine chiffon | D22: Bobine chiffon | E22: Produits | F22: 1000 | G22: 14 | J22: 14 | O22: =IF(AND(J22="",K22="",M22=""),"",IF(OR(AND(N(K22)>0,L22=""),AND(N(M22)>0,N22="")),"à compléter",N(J22)+N(K22)*N(L22)+N(M22)*N(N22))) -> 14
A23: 22 | B23: Garder | C23: Bobine grand | D23: Bobine grand | E23: Produits | F23: 800 | G23: 05 | H23: 24 | J23: 29 | O23: =IF(AND(J23="",K23="",M23=""),"",IF(OR(AND(N(K23)>0,L23=""),AND(N(M23)>0,N23="")),"à compléter",N(J23)+N(K23)*N(L23)+N(M23)*N(N23))) -> 29
A24: 23 | B24: Garder | C24: Bobine petit | D24: Bobine petit | E24: Produits | F24: 500 | G24: 14 | J24: 14 | O24: =IF(AND(J24="",K24="",M24=""),"",IF(OR(AND(N(K24)>0,L24=""),AND(N(M24)>0,N24="")),"à compléter",N(J24)+N(K24)*N(L24)+N(M24)*N(N24))) -> 14
A25: 24 | B25: Garder | C25: Bobine plastique | D25: Bobine plastique | E25: Produits | F25: 1000 | G25: 19 | J25: 19 | O25: =IF(AND(J25="",K25="",M25=""),"",IF(OR(AND(N(K25)>0,L25=""),AND(N(M25)>0,N25="")),"à compléter",N(J25)+N(K25)*N(L25)+N(M25)*N(N25))) -> 19
A26: 25 | B26: Garder | C26: Boîte de produit | D26: Boîte de produit | E26: Produits | F26: 1000 | G26: 16 | J26: 16 | O26: =IF(AND(J26="",K26="",M26=""),"",IF(OR(AND(N(K26)>0,L26=""),AND(N(M26)>0,N26="")),"à compléter",N(J26)+N(K26)*N(L26)+N(M26)*N(N26))) -> 16
A27: 26 | B27: Garder | C27: Boucle en fer | D27: Boucle en fer | E27: Produits | F27: 170 | G27: 4dz+5 | J27: 53 | O27: =IF(AND(J27="",K27="",M27=""),"",IF(OR(AND(N(K27)>0,L27=""),AND(N(M27)>0,N27="")),"à compléter",N(J27)+N(K27)*N(L27)+N(M27)*N(N27))) -> 53
A28: 27 | B28: Garder | C28: Bougie grand | D28: Bougie grand | E28: Produits | F28: 170 | G28: 60 | J28: 60 | O28: =IF(AND(J28="",K28="",M28=""),"",IF(OR(AND(N(K28)>0,L28=""),AND(N(M28)>0,N28="")),"à compléter",N(J28)+N(K28)*N(L28)+N(M28)*N(N28))) -> 60
A29: 28 | B29: Garder | C29: Bougie petit | D29: Bougie petit | E29: Produits | F29: 85 | G29: 64 | J29: 64 | O29: =IF(AND(J29="",K29="",M29=""),"",IF(OR(AND(N(K29)>0,L29=""),AND(N(M29)>0,N29="")),"à compléter",N(J29)+N(K29)*N(L29)+N(M29)*N(N29))) -> 64
A30: 29 | B30: Garder | C30: Brosse grand | D30: Brosse grand | E30: Produits | F30: 700 | G30: 20 | J30: 20 | O30: =IF(AND(J30="",K30="",M30=""),"",IF(OR(AND(N(K30)>0,L30=""),AND(N(M30)>0,N30="")),"à compléter",N(J30)+N(K30)*N(L30)+N(M30)*N(N30))) -> 20
A31: 30 | B31: Garder | C31: Brosse moyen | D31: Brosse moyen | E31: Produits | F31: 600 | G31: 30 | J31: 30 | O31: =IF(AND(J31="",K31="",M31=""),"",IF(OR(AND(N(K31)>0,L31=""),AND(N(M31)>0,N31="")),"à compléter",N(J31)+N(K31)*N(L31)+N(M31)*N(N31))) -> 30
A32: 31 | B32: Garder | C32: Brosse petit | D32: Brosse petit | E32: Produits | F32: 100 | G32: 32 | J32: 32 | O32: =IF(AND(J32="",K32="",M32=""),"",IF(OR(AND(N(K32)>0,L32=""),AND(N(M32)>0,N32="")),"à compléter",N(J32)+N(K32)*N(L32)+N(M32)*N(N32))) -> 32
A33: 32 | B33: Garder | C33: Brosse rond | D33: Brosse rond | E33: Produits | F33: 500 | G33: 07 | J33: 7 | O33: =IF(AND(J33="",K33="",M33=""),"",IF(OR(AND(N(K33)>0,L33=""),AND(N(M33)>0,N33="")),"à compléter",N(J33)+N(K33)*N(L33)+N(M33)*N(N33))) -> 7
A34: 33 | B34: Garder | C34: Brosse still | D34: Brosse still | E34: Produits | F34: 600 | G34: 14 | J34: 14 | O34: =IF(AND(J34="",K34="",M34=""),"",IF(OR(AND(N(K34)>0,L34=""),AND(N(M34)>0,N34="")),"à compléter",N(J34)+N(K34)*N(L34)+N(M34)*N(N34))) -> 14
A35: 34 | B35: Garder | C35: Cache visage | D35: Cache visage | E35: Produits | F35: 700 | G35: 12 | J35: 12 | O35: =IF(AND(J35="",K35="",M35=""),"",IF(OR(AND(N(K35)>0,L35=""),AND(N(M35)>0,N35="")),"à compléter",N(J35)+N(K35)*N(L35)+N(M35)*N(N35))) -> 12
... A38: 37 | B38: Garder | C38: Champoing tokpa grand | D38: Champoing tokpa grand | E38: Produits | F38: 400 | G38: 5dz8 | J38: 68 | O38: =IF(AND(J38="",K38="",M38=""),"",IF(OR(AND(N(K38)>0,L38=""),AND(N(M38)>0,N38="")),"à compléter",N(J38)+N(K38)*N(L38)+N(M38)*N(N38))) -> 68
A39: 38 | B39: Garder | C39: Champoing tokpa petit | D39: Champoing tokpa petit | E39: Produits | F39: 185 | G39: 71 | I39: -6 | J39: 65 | O39: =IF(AND(J39="",K39="",M39=""),"",IF(OR(AND(N(K39)>0,L39=""),AND(N(M39)>0,N39="")),"à compléter",N(J39)+N(K39)*N(L39)+N(M39)*N(N39))) -> 65
A40: 39 | B40: Garder | C40: Chapeau de bain | D40: Chapeau de bain | E40: Produits | F40: 170 | G40: 40 | J40: 40 | O40: =IF(AND(J40="",K40="",M40=""),"",IF(OR(AND(N(K40)>0,L40=""),AND(N(M40)>0,N40="")),"à compléter",N(J40)+N(K40)*N(L40)+N(M40)*N(N40))) -> 40
A41: 40 | B41: Garder | C41: Chapeau cheveux grand | D41: Chapeau cheveux grand | E41: Produits | F41: 800 | G41: 1 | J41: 1 | O41: =IF(AND(J41="",K41="",M41=""),"",IF(OR(AND(N(K41)>0,L41=""),AND(N(M41)>0,N41="")),"à compléter",N(J41)+N(K41)*N(L41)+N(M41)*N(N41))) -> 1
A42: 41 | B42: Garder | C42: Chapeau cheveux petit | D42: Chapeau cheveux petit | E42: Produits | F42: 500 | H42: 12 | J42: 12 | O42: =IF(AND(J42="",K42="",M42=""),"",IF(OR(AND(N(K42)>0,L42=""),AND(N(M42)>0,N42="")),"à compléter",N(J42)+N(K42)*N(L42)+N(M42)*N(N42))) -> 12
A43: 42 | B43: Garder | C43: Chapeau de nuit | D43: Chapeau de nuit | E43: Produits | F43: 500 | G43: 21 | J43: 21 | O43: =IF(AND(J43="",K43="",M43=""),"",IF(OR(AND(N(K43)>0,L43=""),AND(N(M43)>0,N43="")),"à compléter",N(J43)+N(K43)*N(L43)+N(M43)*N(N43))) -> 21
A44: 43 | B44: Garder | C44: Cheveux closure | D44: Cheveux closure | E44: Produits | F44: 2500 | G44: 08 | J44: 8 | O44: =IF(AND(J44="",K44="",M44=""),"",IF(OR(AND(N(K44)>0,L44=""),AND(N(M44)>0,N44="")),"à compléter",N(J44)+N(K44)*N(L44)+N(M44)*N(N44))) -> 8
A45: 44 | B45: Garder | C45: Chiffon coiffé petit | D45: Chiffon coiffé petit | E45: Produits | F45: 1000 | G45: 06 | J45: 6 | O45: =IF(AND(J45="",K45="",M45=""),"",IF(OR(AND(N(K45)>0,L45=""),AND(N(M45)>0,N45="")),"à compléter",N(J45)+N(K45)*N(L45)+N(M45)*N(N45))) -> 6
...
